Workbook
Name table: #REF!
Name table1: #REF!
Name table2: #REF!
Name table3: #REF!

Sheet 展示总表
A2: LCOS= | D2: CAPEX | G2: + | H2: OPEX | J2: + | K2: 累计充电电费 | M2: = | N2: =(D6+E6+F6+H6+K6)/D12 -> 0.277282 | S2: 净利润 | U2: 充电电费
R3: =(D6+E6+F6)/10000 -> 25396.39 | S3: =经济性测算!B23/10000 -> 99172.473 | T3: 万元 | U3: =K6/10000 -> 22472.978 | W3: =(D6+E6+F6) -> 2.539639e+08 | X3: 1.1101192e+08
D4: 直流侧成本 | E4: 交流侧成本 | F4: 施工基建成本 | H4: 运维成本 | R4: =H6/10000 -> 6118.4121 | X4: 1.2192215e+08
R5: =K6/10000 -> 22472.978 | S5: IRR | U5: 放电电量 | W5: =X5/100000000 -> 0.10910224 | X5: =X4-X3 -> 10910224
D6: =直流侧成本构成!D2 -> 176964480 | E6: =交流侧成本构成!D1 -> 34338000 | F6: =施工耗材基建成本构成!D1 -> 42661417 | H6: =运营期间费用构成!E1 -> 61184121 | K6: =累计充电电费及累计放电量!F1 -> 2.2472978e+08 | R6: =D12/10000 -> 194703.51 | S6: =经济性测算!B25 -> 0.17124928 | U6: =D12/10000 -> 194703.51 | X6: =X5/X4 -> 0.089485172
D7: ————————————————————————————————————
D8: 累计放电电量 | S8: 回收年限 | X8: 40035627
S9: =经济性测算!B28 -> 5.2744698 | T9: 年 | X9: 42498761
X10: =X9-X8 -> 2463133.7
S11: 面积 | X11: =X10/X9 -> 0.057957778
D12: =累计充电电费及累计放电量!B2 -> 1.9470351e+09 | S12: =直流侧成本构成!N2 -> 8600 | T12: ㎡
A14: LCOE= | D14: CAPEX | G14: + | H14: OPEX | J14: — | K14: 设备残值 | M14: = | N14: =((D18+E18+F18+H18-K18)/D24) -> 0.15643421 | X14: 9.5431866e+08
X15: 9.5175843e+08
D16: 直流侧成本 | E16: 交流侧成本 | F16: 施工基建成本 | H16: 运维成本 | V16: 36850.6 | X16: =X15-X14 -> -2560227.7
V17: 36856.584 | X17: =X16/X15 -> -0.0026899974
D18: =D6 -> 176964480 | E18: =E6 -> 34338000 | F18: =F6 -> 42661417 | H18: =H6 -> 61184121 | K18: =0.05*(D18+E18) -> 10565124 | V18: =V16-V17 -> -5.9843352
D19: ————————————————————————————————————
D20: 累计放电电量 | U20: =X14*0.8-330446764 -> 4.3300816e+08
U21: =X15*0.8-331306107 -> 4.3010064e+08
U22: =U20-U21 -> 2907525.2
U23: =U22/100000000 -> 0.029075252
D24: =D12 -> 1.9470351e+09
F26: 314 | G26: 314B | S26: 0.52085382
D27: capex | E27: =SUM(D6:F6) -> 2.539639e+08 | F27: 1.2192215e+08 | G27: 1.2753316e+08 | H27: =G27-F27 -> 5611007.8 | I27: =H27/F27 -> 0.046021235 | S27: 0.50454249
D28: opex | E28: =E27/10000 -> 25396.39 | F28: 42498761 | G28: 42667091 | H28: =G28-F28 -> 168330.24 | I28: =H28/F28 -> 0.0039608269 | S28: =S26-S27 -> 0.016311329
C29: =D6+E6 -> 211302480 | D29: 电费 | F29: 3.3130611e+08 | G29: 3.4821058e+08 | H29: =G29-F29 -> 16904468 | I29: =H29/F29 -> 0.051023714 | S29: =S28/S26 -> 0.03131652
C30: =C29/400/1000/1000 -> 0.5282562 | D30: 电量 | F30: 9.5175843e+08 | G30: 1.0003207e+09 | H30: =G30-F30 -> 48562250 | I30: =H30/F30 -> 0.051023714 | J30: =G30*0.8-G29-F30*0.8+F29 -> 21945332
E31: =H6/10000 -> 6118.4121 | F31: 0.52085382 | G31: 0.51824463 | H31: =G31-F31 -> -0.0026091906 | I31: =H31/F31 -> -0.0050094489 | J31: =J30/100000000 -> 0.21945332
E33: =K6/10000 -> 22472.978
E34: =D12/10000 -> 194703.51

Sheet 直流侧成本构成
A1: 直流侧类型 | D1: 200MWh直流侧总成本（单位：元） | G1: 集装箱数量 | H1: 单集装箱240mm主正出线数量 | P1: 集装箱价格
A2: CALB314B-5.0 | D2: =G2*Q2 -> 176964480 | G2: =IF(A2=M2,64,IF(A2=M3,64,IF(A2=M4,68,IF(A2=M5,60,IF(A2=M6,58,IF(A2=M7,80,IF(A2=M8,80))))))) -> 80 | H2: 6 | K2: =200/6.9 -> 28.985507 | M2: CALB392-6.25 | N2: =IF(A2=M2,7320,IF(A2=M3,7200,IF(A2=M4,7626,IF(A2=M5,6900,IF(A2=M6,6870,IF(A2=M7,8600,IF(A2=M8,8600))))))) -> 8600 | P2: =323.84*6250*1.13 -> 2287120 | Q2: =IF(A2=M2,P2,IF(A2=M3,P3,IF(A2=M4,P4,IF(A2=M5,P5,IF(A2=M6,P6,IF(A2=M7,P7,IF(A2=M8,P8))))))) -> 2212056 | R2: =SQRT(S2) -> 0.97467943 | S2: 0.95
M3: CATL588-6.26 | N3: =IF(A2=M2,220000,IF(A2=M3,220000,IF(A2=M4,210000,IF(A2=M5,240000,IF(A2=M6,240000,IF(A2=M7,170000,IF(A2=M8,170000))))))) -> 170000 | P3: =305.06*6260*1.13 -> 2157933.4 | R3: =SQRT(S3) -> 0.97159662 | S3: 0.944
G4: 占地面积 | M4: CATL565-6 | N4: =IF(A2=M2,290000,IF(A2=M3,290000,IF(A2=M4,270000,IF(A2=M5,300000,IF(A2=M6,320000,IF(A2=M7,220000,IF(A2=M8,220000))))))) -> 220000 | P4: =320.63*6000*1.13 -> 2173871.4 | R4: =SQRT(S4) -> 0.9721111 | S4: 0.945
G5: =N2 -> 8600 | M5: 640A-6.68 | N5: =IF(A2=M2,R2,IF(A2=M3,R3,IF(A2=M4,R4,IF(A2=M5,R5,IF(A2=M6,R6,IF(A2=M7,R7,IF(A2=M8,R8))))))) -> 0.97467943 | P5: =310.36*6680*1.13 -> 2342721.4 | R5: =SQRT(S5) -> 0.9721111 | S5: 0.945
M6: 中车648-6.9 | P6: =310.04*6900*1.13 -> 2417381.9 | R6: =SQRT(S6) -> 0.97159662 | S6: 0.944
G7: 直流侧效率 | M7: CALB314-5.0 | P7: =N11 -> 1986336 | R7: =SQRT(S7) -> 0.9721111 | S7: 0.945
G8: =N5 -> 0.97467943 | K8: =127.25*30.46 -> 3876.035 | M8: CALB314B-5.0 | P8: =O10 -> 2212056 | R8: =SQRT(S8) -> 0.97467943 | S8: 0.95
H10: =P2/6250/1000 -> 0.3659392 | N10: =0.291+0.105 -> 0.396 | O10: =(0.336+0.105)*5016*1000 -> 2212056
H11: 0.0829 | N11: =N10*5016*1000 -> 1986336 | P11: =P7/5016 -> 396
H12: =SUM(H10:H11) -> 0.4488392 | P12: =P11-100 -> 296

Sheet 交流侧成本构成
A1: 交流侧成本 | D1: =F3+F10+F17+F22 -> 34338000 | G1: 元
A2: 序号 | B2: BOM明细 | C2: 数量 | D2: 单位 | E2: 分项成本 | F2: 分项总价
A3: 1 | B3: 变流升压一体机 | C3: =直流侧成本构成!G2/2 -> 40 | D3: 套 | E3: =F4+F5+F6+F7+F8+F9 -> 830000 | F3: =C3*E3 -> 33200000
A4: 1.1 | B4: 变流器 | C4: 2 | D4: 台 | E4: =直流侧成本构成!N3 -> 170000 | F4: =C4*E4 -> 340000 | H4: =D1/200/1000/1000 -> 0.17169
A5: 1.2 | B5: 升压变压器 | C5: 1 | D5: 台 | E5: =直流侧成本构成!N4 -> 220000 | F5: =C5*E5 -> 220000
A6: 1.3 | B6: 辅助变压器 | C6: 1 | D6: 台 | E6: 40000 | F6: =C6*E6 -> 40000
A7: 1.4 | B7: 高压柜 | C7: 1 | D7: 台 | E7: 80000 | F7: =C7*E7 -> 80000
A8: 1.5 | B8: 低压配电柜 | C8: 1 | D8: 台 | E8: 20000 | F8: =C8*E8 -> 20000
A9: 1.6 | B9: 箱体及其他附件 | C9: 1 | D9: 套 | E9: 130000 | F9: =C9*E9 -> 130000
A10: 2 | B10: 能量管理系统 | C10: 2 | D10: 套 | E10: =F11+F12+F13+F14+F15+F16 -> 542000 | F10: =C10*E10 -> 1084000
A11: 2.1 | B11: 本地服务器 | C11: 2 | D11: 台 | E11: 100000 | F11: =C11*E11 -> 200000
A12: 2.2 | B12: 电脑显示器 | C12: 4 | D12: 台 | E12: 2000 | F12: =C12*E12 -> 8000
A13: 2.3 | B13: 操作软件 | C13: 2 | D13: 套 | E13: 40000 | F13: =C13*E13 -> 80000
A14: 2.4 | B14: 协调控制器 | C14: 2 | D14: 台 | E14: 120000 | F14: =C14*E14 -> 240000
A15: 2.5 | B15: 操作台 | C15: 2 | D15: 台 | E15: 4000 | F15: =C15*E15 -> 8000
A16: 2.6 | B16: 计量装置 | C16: 2 | D16: 套 | E16: 3000 | F16: =C16*E16 -> 6000
A17: 3 | B17: 备品备件 | C17: 2 | D17: 套 | F17: =SUM(F18:F21) -> 49000
A18: 3.1 | B18: PCS直流侧熔断器 | C18: 3 | D18: 个 | E18: 5000 | F18: =C18*E18 -> 15000
A19: 3.2 | B19: PCS直流侧防雷 | C19: 3 | D19: 个 | E19: 3000 | F19: =C19*E19 -> 9000
A20: 3.3 | B20: PCS交流侧防雷 | C20: 3 | D20: 个 | E20: 3000 | F20: =C20*E20 -> 9000
A21: 3.4 | B21: 风扇 | C21: =C3*C4 -> 80 | D21: 个 | E21: 200 | F21: =C21*E21 -> 16000
A22: 4 | B22: 一次性工具 | C22: 1 | D22: 套 | F22: =F23 -> 5000
A23: 4.1 | B23: 吊具 | C23: 1 | D23: 套 | E23: 5000 | F23: =C23*E23 -> 5000

Sheet 施工耗材基建成本构成
A1: 基建、施工、耗材、一次性支出成本 | D1: =F3+F4+F5+F14+F19+F44+F31+F37 -> 42661417 | G1: 元
A2: 序号 | B2: BOM明细 | C2: 数量 | D2: 单位 | E2: 分项成本 | F2: 分项总价
A3: 1 | B3: 设计费 | C3: 1 | D3: 元 | E3: =累计充电电费及累计放电量!J5*1000*3.5 -> 1400000 | F3: =C3*E3 -> 1400000
A4: 2 | B4: 监理费 | C4: 1 | D4: 元 | E4: =累计充电电费及累计放电量!J5*1000*2 -> 800000 | F4: =C4*E4 -> 800000
A5: 3 | B5: 线缆及辅材 | C5: 1 | D5: 套 | E5: —— | F5: =SUM(F6:F13) -> 3247800
A6: 3.1 | B6: 舱体—PCS直流线缆（240m㎡） | C6: =7*直流侧成本构成!G2*直流侧成本构成!H2*2 -> 6720 | D6: m | E6: 420 | F6: =C6*E6 -> 2822400 | J6: =D1 -> 42661417
A7: 3.3 | B7: 辅助变—舱体交流线缆（35m㎡） | C7: =10*直流侧成本构成!G2 -> 800 | D7: m | E7: 120 | F7: =C7*E7 -> 96000 | J7: =J6/100/1000/1000 -> 0.42661417
A8: 3.4 | B8: 站用变—配电柜交流线缆（35m㎡） | C8: =直流侧成本构成!G2/10*100 -> 800 | D8: m | E8: 120 | F8: =C8*E8 -> 96000
A9: 3.5 | B9: 配电柜—ATS交流线缆（4m㎡） | C9: =30*直流侧成本构成!G2 -> 2400 | D9: m | E9: 12 | F9: =C9*E9 -> 28800
A10: 3.6 | B10: 信号线及光纤 | C10: =C7*2 -> 1600 | D10: m | E10: 6 | F10: =C10*E10 -> 9600
A11: 3.7 | B11: 高压室—并网柜线缆（120m㎡） | C11: 200 | D11: m | E11: 300 | F11: =C11*E11 -> 60000
A12: 3.8 | B12: 接地变压器（400V）-重要负载 | C12: 1 | D12: 台 | E12: 130000 | F12: =C12*E12 -> 130000
A13: 3.9 | B13: 接线辅材 | C13: 1 | D13: 套 | E13: 5000 | F13: =C13*E13 -> 5000
A14: 4 | B14: 并网设备 | C14: 1 | D14: 套 | F14: =SUM(F15:F18) -> 15720000
A15: 4.1 | B15: 并网柜 | C15: 8 | D15: 台 | E15: 250000 | F15: =C15*E15 -> 2000000
A16: 4.2 | B16: 联络柜（如需） | C16: 1 | D16: 台 | E16: 220000 | F16: =C16*E16 -> 220000
A17: 4.3 | B17: 箱式主变（如需） | C17: 2 | D17: 台 | E17: 6000000 | F17: =C17*E17 -> 12000000
A18: 4.4 | B18: 二次仓（如需） | C18: 1 | D18: 台 | E18: 1500000 | F18: =C18*E18 -> 1500000
A19: 5 | B19: 基础土建 | C19: 1 | D19: 套 | F19: =SUM(F20:F30) -> 11996666
A20: 5.1 | B20: 破硬化路面（如需） | C20: =运营期间费用构成!C14*0.3 -> 2580 | D20: m³ | E20: 600 | F20: =C20*E20 -> 1548000
A21: 5.2 | B21: 土方开挖 | C21: =(6.242*2.6*3*直流侧成本构成!G2)+(7*3.5*3*交流侧成本构成!C3)+(直流侧成本构成!G2*7*1.5*2)+施工耗材基建成本构成!C11*1.5*1.5 -> 8965.008 | D21: m³ | E21: 400 | F21: =C21*E21 -> 3586003.2
A22: 5.3 | B22: 钢结构搭建 | C22: =16*C23/1000 -> 55.7952 | D22: 吨 | E22: 6000 | F22: =C22*E22 -> 334771.2
A23: 5.4 | B23: 混凝土浇筑 | C23: =((6.6*2+2.8*2)*0.35*3*直流侧成本构成!G2)+((7*2+3.5*2)*0.35*3*交流侧成本构成!C3)+(直流侧成本构成!G2*7*4.5*0.3)+施工耗材基建成本构成!C11*4.5*0.3 -> 3487.2 | D23: m³ | E23: 450 | F23: =C23*E23 -> 1569240
A24: 5.5 | B24: 槽钢铺设 | C24: =30*直流侧成本构成!G2/1000 -> 2.4 | D24: 吨 | E24: =E22 -> 6000 | F24: =C24*E24 -> 14400
A25: 5.6 | B25: 电缆桥架 | C25: =180*直流侧成本构成!G2/1000+C11/0.5*4/1000 -> 16 | D25: 吨 | E25: =E22 -> 6000 | F25: =C25*E25 -> 96000
A26: 5.7 | B26: 路面硬化 | C26: =C20*0.3 -> 774 | D26: m³ | E26: 450 | F26: =C26*E26 -> 348300
A27: 5.8 | B27: 人工费用 | C27: 400 | D27: 元/人/日 | E27: =累计充电电费及累计放电量!J5*4 -> 1600 | F27: =C27*E27 -> 640000
A28: 5.9 | B28: 土方清运 | C28: =C21+C36 -> 9733.008 | D28: m³ | E28: 150 | F28: =C28*E28 -> 1459951.2
A29: 5.1 | B29: 电气安装工程 | C29: 1 | D29: 元 | E29: =累计充电电费及累计放电量!J5*1000*3 -> 1200000 | F29: =C29*E29 -> 1200000
A30: 5.11 | B30: 其他建工费用 | C30: 1 | D30: 元 | E30: =E29 -> 1200000 | F30: =C30*E30 -> 1200000
A31: 6 | B31: 站区消防 | C31: 1 | D31: 套 | F31: =SUM(F32:F36) -> 791800
A32: 6.1 | B32: 消防池 | C32: 500 | D32: m³ | E32: 350 | F32: =C32*E32 -> 175000
A33: 6.2 | B33: 消防水泵 | C33: 2 | D33: 套 | E33: 4000 | F33: =C33*E33 -> 8000
A34: 6.3 | B34: 消防水管 | C34: =C9 -> 2400 | D34: m | E34: 20 | F34: =C34*E34 -> 48000
A35: 6.4 | B35: 施工杂费 | C35: 1 | D35: 套 | E35: 100000 | F35: =C35*E35 -> 100000
A36: 6.5 | B36: 消防土建 | C36: =C34*0.4*0.8 -> 768 | D36: m³ | E36: 600 | F36: =C36*E36 -> 460800
A37: 7 | B37: 站区安防 | C37: 1 | D37: 套 | F37: =SUM(F38:F43) -> 636695.19
A38: 7.1 | B38: 预制监控室 | C38: 1 | D38: 套 | E38: 300000 | F38: =C38*E38 -> 300000
A39: 7.2 | B39: 消防主机 | C39: 1 | D39: 套 | E39: 40000 | F39: =C39*E39 -> 40000
A40: 7.3 | B40: 监控主机 | C40: 1 | D40: 套 | E40: 25000 | F40: =C40*E40 -> 25000
...

Sheet 运营期间费用构成
B1: 运营费用 | E1: =SUM(C11:V11) -> 61184121 | H1: 元
A2: 序号 | B2: 费用构成 | C2: 1 | D2: 2 | E2: 3 | F2: 4 | G2: 5 | H2: 6 | I2: 7 | J2: 8 | K2: 9 | L2: 10 | M2: 11 | N2: 12 | O2: 13 | P2: 14 | Q2: 15 | R2: 16 | S2: 17 | T2: 18 | U2: 19 | V2: 20
A3: 1 | B3: 场地租金 | C3: =IF(累计充电电费及累计放电量!$J$9+1>运营期间费用构成!C2,运营期间费用构成!$C$13*运营期间费用构成!$C$14,0) -> 0 | D3: =IF(累计充电电费及累计放电量!$J$9+1>运营期间费用构成!D2,运营期间费用构成!$C$13*运营期间费用构成!$C$14,0) -> 0 | E3: =IF(累计充电电费及累计放电量!$J$9+1>运营期间费用构成!E2,运营期间费用构成!$C$13*运营期间费用构成!$C$14,0) -> 0 | F3: =IF(累计充电电费及累计放电量!$J$9+1>运营期间费用构成!F2,运营期间费用构成!$C$13*运营期间费用构成!$C$14,0) -> 0 | G3: =IF(累计充电电费及累计放电量!$J$9+1>运营期间费用构成!G2,运营期间费用构成!$C$13*运营期间费用构成!$C$14,0) -> 0 | H3: =IF(累计充电电费及累计放电量!$J$9+1>运营期间费用构成!H2,运营期间费用构成!$C$13*运营期间费用构成!$C$14,0) -> 0 | I3: =IF(累计充电电费及累计放电量!$J$9+1>运营期间费用构成!I2,运营期间费用构成!$C$13*运营期间费用构成!$C$14,0) -> 0 | J3: =IF(累计充电电费及累计放电量!$J$9+1>运营期间费用构成!J2,运营期间费用构成!$C$13*运营期间费用构成!$C$14,0) -> 0 | ... V3: =IF(累计充电电费及累计放电量!$J$9+1>运营期间费用构成!V2,运营期间费用构成!$C$13*运营期间费用构成!$C$14,0) -> 0
A4: 2 | B4: 运维费用 | C4: =C5+C6 -> 990000 | D4: =D5+D6 -> 990000 | E4: =E5+E6 -> 990000 | F4: =F5+F6 -> 990000 | G4: =G5+G6 -> 990000 | H4: =H5+H6 -> 990000 | I4: =I5+I6 -> 990000 | J4: =J5+J6 -> 990000 | ... V4: =V5+V6 -> 0
A5: 2.1 | B5: 人工费 | C5: =IF(累计充电电费及累计放电量!$J$9+1>运营期间费用构成!C2,$C$15,0) -> 960000 | D5: =IF(累计充电电费及累计放电量!$J$9+1>运营期间费用构成!D2,$C$15,0) -> 960000 | E5: =IF(累计充电电费及累计放电量!$J$9+1>运营期间费用构成!E2,$C$15,0) -> 960000 | F5: =IF(累计充电电费及累计放电量!$J$9+1>运营期间费用构成!F2,$C$15,0) -> 960000 | G5: =IF(累计充电电费及累计放电量!$J$9+1>运营期间费用构成!G2,$C$15,0) -> 960000 | H5: =IF(累计充电电费及累计放电量!$J$9+1>运营期间费用构成!H2,$C$15,0) -> 960000 | I5: =IF(累计充电电费及累计放电量!$J$9+1>运营期间费用构成!I2,$C$15,0) -> 960000 | J5: =IF(累计充电电费及累计放电量!$J$9+1>运营期间费用构成!J2,$C$15,0) -> 960000 | ... V5: =IF(累计充电电费及累计放电量!$J$9+1>运营期间费用构成!V2,$C$15,0) -> 0
A6: 2.2 | B6: 云平台费用 | C6: =IF(累计充电电费及累计放电量!$J$9+1>运营期间费用构成!C2,$C$16,0) -> 30000 | D6: =IF(累计充电电费及累计放电量!$J$9+1>运营期间费用构成!D2,$C$16,0) -> 30000 | E6: =IF(累计充电电费及累计放电量!$J$9+1>运营期间费用构成!E2,$C$16,0) -> 30000 | F6: =IF(累计充电电费及累计放电量!$J$9+1>运营期间费用构成!F2,$C$16,0) -> 30000 | G6: =IF(累计充电电费及累计放电量!$J$9+1>运营期间费用构成!G2,$C$16,0) -> 30000 | H6: =IF(累计充电电费及累计放电量!$J$9+1>运营期间费用构成!H2,$C$16,0) -> 30000 | I6: =IF(累计充电电费及累计放电量!$J$9+1>运营期间费用构成!I2,$C$16,0) -> 30000 | J6: =IF(累计充电电费及累计放电量!$J$9+1>运营期间费用构成!J2,$C$16,0) -> 30000 | ... V6: =IF(累计充电电费及累计放电量!$J$9+1>运营期间费用构成!V2,$C$16,0) -> 0
A7: 3 | B7: 设备更换费用 | C7: =IF(累计充电电费及累计放电量!$J$9+1>运营期间费用构成!C2,C8+C9,0) -> 1600000 | D7: =IF(累计充电电费及累计放电量!$J$9+1>运营期间费用构成!D2,D8+D9,0) -> 1600000 | E7: =IF(累计充电电费及累计放电量!$J$9+1>运营期间费用构成!E2,E8+E9,0) -> 1840000 | F7: =IF(累计充电电费及累计放电量!$J$9+1>运营期间费用构成!F2,F8+F9,0) -> 1600000 | G7: =IF(累计充电电费及累计放电量!$J$9+1>运营期间费用构成!G2,G8+G9,0) -> 1904000 | H7: =IF(累计充电电费及累计放电量!$J$9+1>运营期间费用构成!H2,H8+H9,0) -> 1840000 | I7: =IF(累计充电电费及累计放电量!$J$9+1>运营期间费用构成!I2,I8+I9,0) -> 1600000 | J7: =IF(累计充电电费及累计放电量!$J$9+1>运营期间费用构成!J2,J8+J9,0) -> 1600000 | ... V7: =IF(累计充电电费及累计放电量!$J$9+1>运营期间费用构成!V2,V8+V9,0) -> 0
A8: 3.1 | B8: 定期设备更换 | C8: =C21*直流侧成本构成!$G$2 -> 0 | D8: =D21*直流侧成本构成!$G$2 -> 0 | E8: =E21*直流侧成本构成!$G$2 -> 240000 | F8: =F21*直流侧成本构成!$G$2 -> 0 | G8: =G21*直流侧成本构成!$G$2 -> 304000 | H8: =H21*直流侧成本构成!$G$2 -> 240000 | I8: =I21*直流侧成本构成!$G$2 -> 0 | J8: =J21*直流侧成本构成!$G$2 -> 0 | ... V8: =V21*直流侧成本构成!$G$2 -> 304000
A9: 3.2 | B9: 损坏设备更换 | C9: =IF(累计充电电费及累计放电量!$J$9+1>运营期间费用构成!C2,C26,0) -> 1600000 | D9: =IF(累计充电电费及累计放电量!$J$9+1>运营期间费用构成!D2,D26,0) -> 1600000 | E9: =IF(累计充电电费及累计放电量!$J$9+1>运营期间费用构成!E2,E26,0) -> 1600000 | F9: =IF(累计充电电费及累计放电量!$J$9+1>运营期间费用构成!F2,F26,0) -> 1600000 | G9: =IF(累计充电电费及累计放电量!$J$9+1>运营期间费用构成!G2,G26,0) -> 1600000 | H9: =IF(累计充电电费及累计放电量!$J$9+1>运营期间费用构成!H2,H26,0) -> 1600000 | I9: =IF(累计充电电费及累计放电量!$J$9+1>运营期间费用构成!I2,I26,0) -> 1600000 | J9: =IF(累计充电电费及累计放电量!$J$9+1>运营期间费用构成!J2,J26,0) -> 1600000 | ... V9: =IF(累计充电电费及累计放电量!$J$9+1>运营期间费用构成!V2,V26,0) -> 0
A10: 4 | B10: 保险费 | C10: =IF(累计充电电费及累计放电量!$J$9+1>运营期间费用构成!C2,$C$18,0) -> 316953.72 | D10: =IF(累计充电电费及累计放电量!$J$9+1>运营期间费用构成!D2,$C$18,0) -> 316953.72 | E10: =IF(累计充电电费及累计放电量!$J$9+1>运营期间费用构成!E2,$C$18,0) -> 316953.72 | F10: =IF(累计充电电费及累计放电量!$J$9+1>运营期间费用构成!F2,$C$18,0) -> 316953.72 | G10: =IF(累计充电电费及累计放电量!$J$9+1>运营期间费用构成!G2,$C$18,0) -> 316953.72 | H10: =IF(累计充电电费及累计放电量!$J$9+1>运营期间费用构成!H2,$C$18,0) -> 316953.72 | I10: =IF(累计充电电费及累计放电量!$J$9+1>运营期间费用构成!I2,$C$18,0) -> 316953.72 | J10: =IF(累计充电电费及累计放电量!$J$9+1>运营期间费用构成!J2,$C$18,0) -> 316953.72 | ... V10: =IF(累计充电电费及累计放电量!$J$9+1>运营期间费用构成!V2,$C$18,0) -> 0
A11: 5 | B11: 合计 | C11: =C3+C4+C7+C10 -> 2906953.7 | D11: =D3+D4+D7+D10 -> 2906953.7 | E11: =E3+E4+E7+E10 -> 3146953.7 | F11: =F3+F4+F7+F10 -> 2906953.7 | G11: =G3+G4+G7+G10 -> 3210953.7 | H11: =H3+H4+H7+H10 -> 3146953.7 | I11: =I3+I4+I7+I10 -> 2906953.7 | J11: =J3+J4+J7+J10 -> 2906953.7 | ... V11: =V3+V4+V7+V10 -> 0
A13: 参数设置 | B13: 场地租金 | C13: 0 | D13: 元/㎡/年
B14: 占地面积 | C14: =直流侧成本构成!N2 -> 8600 | D14: ㎡
B15: 人工费 | C15: =12000*直流侧成本构成!G2 -> 960000 | D15: 元/年 | E15: 维护费。单台集装箱12000元
B16: 云平台费 | C16: 30000 | D16: 元/年
B17: 保险费比例 | C17: 0.15 | D17: %
B18: 保险费用 | C18: =(直流侧成本构成!D2+交流侧成本构成!D1)*运营期间费用构成!C17/100 -> 316953.72 | D18: 元/年
A20: 设备更换费用 | B20: 年份 | C20: 1 | D20: 2 | E20: 3 | F20: 4 | G20: 5 | H20: 6 | I20: 7 | J20: 8 | K20: 9 | L20: 10 | M20: 11 | N20: 12 | O20: 13 | P20: 14 | Q20: 15 | R20: 16 | S20: 17 | T20: 18 | U20: 19 | V20: 20
B21: 定期设备更换 | C21: =SUM(C22:C25) -> 0 | D21: =SUM(D22:D25) -> 0 | E21: =SUM(E22:E25) -> 3000 | F21: =SUM(F22:F25) -> 0 | G21: =SUM(G22:G25) -> 3800 | H21: =SUM(H22:H25) -> 3000 | I21: =SUM(I22:I25) -> 0 | J21: =SUM(J22:J25) -> 0 | ... V21: =SUM(V22:V25) -> 3800
B22: 照明 | G22: 500 | L22: 500 | Q22: 500 | V22: 500
B23: 高压箱断路器 | G23: 1600 | L23: 1600 | Q23: 1600 | V23: 1600
B24: 高压箱熔断器 | G24: 1700 | L24: 1700 | Q24: 1700 | V24: 1700
B25: 舱级探测器 | E25: 3000 | H25: 3000 | K25: 3000 | N25: 3000 | Q25: 3000 | T25: 3000
B26: 随机损坏设备更换 | C26: =0.004*累计充电电费及累计放电量!$J$5*1000*1000 -> 1600000 | D26: =0.004*累计充电电费及累计放电量!$J$5*1000*1000 -> 1600000 | E26: =0.004*累计充电电费及累计放电量!$J$5*1000*1000 -> 1600000 | F26: =0.004*累计充电电费及累计放电量!$J$5*1000*1000 -> 1600000 | G26: =0.004*累计充电电费及累计放电量!$J$5*1000*1000 -> 1600000 | H26: =0.004*累计充电电费及累计放电量!$J$5*1000*1000 -> 1600000 | I26: =0.004*累计充电电费及累计放电量!$J$5*1000*1000 -> 1600000 | J26: =0.004*累计充电电费及累计放电量!$J$5*1000*1000 -> 1600000 | ... L26: =0.004*累计充电电费及累计放电量!$J$5*1000*1000 -> 1600000 | M26: 2000000 | N26: 2000000 | O26: 2000000 | P26: 2000000 | Q26: 2000000 | R26: 2000000 | S26: 2000000 | T26: 2000000 | U26: 2000000 | V26: 2000000

Sheet 累计充电电费及累计放电量
A1: 累计充电量 | B1: =V76 -> 2.2472978e+09 | C1: kWh | E1: 累计充电电费 | F1: =B1*J12 -> 2.2472978e+08 | G1: 元 | L1: =B2/10000 -> 194703.51
A2: 累计放电量 | B2: =V77 -> 1.9470351e+09 | C2: kWh | E2: 累计放电电费 | F2: =B2*J13 -> 8.4501325e+08 | G2: 元
G4: 使用工况 | H4: 储能系统功率 | J4: 200 | K4: MW
A5: 系统效率 | B5: 充电效率 | D5: =J5*J6*1000/(J5*J6*1000/(D8*D9*D10*D11*D12)+D13) -> 0.93179396 | E5: % | H5: 储能系统总容量 | J5: 400 | K5: MWh | V5: CALB392-6.25
B6: 放电效率 | D6: =((D8*D9*D10*D11*D12)*J5*J6*1000-D13)/(J5*J6*1000) -> 0.92980799 | E6: % | H6: 单次充放电深度 | J6: 0.95 | K6: % | V6: CATL588-6.26
B7: 系统综合效率 | D7: =D5*D6 -> 0.86638947 | E7: % | H7: 产品型号 | J7: =直流侧成本构成!A2 -> CALB314B-5.0 | V7: CATL565-6
B8: 直流侧效率 | D8: =直流侧成本构成!G8 -> 0.97467943 | E8: % | H8: 年循环次数 | J8: 350 | K8: 次 | V8: 640A-6.68
B9: PCS效率 | D9: 0.985 | E9: % | H9: 使用年限 | J9: 19 | K9: 年 | V9: 中车648-6.9
B10: 升压效率 | D10: 0.989 | E10: % | H10: 总循环次数 | J10: =J8*J9 -> 6650 | K10: 次 | V10: CALB314-5.0
B11: 元器件及线缆损耗 | D11: 0.997 | E11: % | V11: CALB314B-5.0
B12: 温度修正系数 | D12: 1 | E12: % | G12: 充放电费 | H12: 市场化购电电价 | J12: 0.1 | K12: 元/kWh
B13: 充/放单次自用电 | D13: 6400 | E13: kWh | H13: 市场化放电电价 | J13: 0.434 | K13: 元/kWh
B14: 待机损耗功率 | D14: 320 | E14: kW | G14: 调频收益 | J14: 100000 | K14: 元/MW
B15: 待机损耗电量 | D15: =320*20 -> 6400 | E15: kWh | G15: 容量电价 | J15: 100 | K15: 元/kW/年
B16: 全天综合能效 | D16: =((D8*D9*D10*D11*D12)*J5*J6*1000-D13)/(J5*J6*1000/(D8*D9*D10*D11*D12)+D13+D15) -> 0.85300298 | E16: %
A18: CALB392-6.25剩余容量
B19: 1 | C19: 2 | D19: 3 | E19: 4 | F19: 5 | G19: 6 | H19: 7 | I19: 8 | J19: 9 | K19: 10 | L19: 11 | M19: 12 | N19: 13 | O19: 14 | P19: 15 | Q19: 16 | R19: 17 | S19: 18 | T19: 19 | U19: 20
A20: 年初 | B20: 1 | C20: 0.961 | D20: 0.932 | E20: 0.906 | F20: 0.882 | G20: 0.86 | H20: 0.839 | I20: 0.819 | J20: 0.799 | K20: 0.78 | L20: 0.762 | M20: 0.744 | N20: 0.727 | O20: 0.709 | P20: 0.692 | Q20: 0.676 | R20: 0.659 | S20: 0.643 | T20: 0.626 | U20: 0.61
A21: 年末 | B21: 0.952 | C21: 0.917 | D21: 0.886 | E21: 0.858 | F21: 0.831 | G21: 0.806 | H21: 0.782 | I21: 0.758 | J21: 0.736 | K21: 0.714 | L21: 0.692 | M21: 0.671 | N21: 0.65 | O21: 0.63 | P21: 0.61 | Q21: 0.59 | R21: 0.57 | S21: 0.551 | T21: 0.532 | U21: 0.512
A22: 综合 | B22: =(B20+B21)/2 -> 0.976 | C22: =(C20+C21)/2 -> 0.939 | D22: =(D20+D21)/2 -> 0.909 | E22: =(E20+E21)/2 -> 0.882 | F22: =(F20+F21)/2 -> 0.8565 | G22: =(G20+G21)/2 -> 0.833 | H22: =(H20+H21)/2 -> 0.8105 | I22: =(I20+I21)/2 -> 0.7885 | ... U22: =(U20+U21)/2 -> 0.561
A23: CATL588-6.26剩余容量
B24: 1 | C24: 2 | D24: 3 | E24: 4 | F24: 5 | G24: 6 | H24: 7 | I24: 8 | J24: 9 | K24: 10 | L24: 11 | M24: 12 | N24: 13 | O24: 14 | P24: 15 | Q24: 16 | R24: 17 | S24: 18 | T24: 19 | U24: 20
A25: 年初 | B25: 1 | C25: 0.959 | D25: 0.9299 | E25: 0.90384 | F25: 0.8798 | G25: 0.85776 | H25: 0.83672 | I25: 0.81668 | J25: 0.79664 | K25: 0.776 | L25: 0.756 | M25: 0.736 | N25: 0.717 | O25: 0.697 | P25: 0.678 | Q25: 0.66 | R25: 0.6392 | S25: 0.620328 | T25: 0.602892 | U25: 0.586238 | V25: 0.569584
A26: 年末 | B26: =C25 -> 0.959 | C26: =D25 -> 0.9299 | D26: =E25 -> 0.90384 | E26: =F25 -> 0.8798 | F26: =G25 -> 0.85776 | G26: =H25 -> 0.83672 | H26: =I25 -> 0.81668 | I26: =J25 -> 0.79664 | ... T26: =U25 -> 0.586238 | U26: 0.569584
A27: 综合 | B27: =(B25+B26)/2 -> 0.9795 | C27: =(C25+C26)/2 -> 0.94445 | D27: =(D25+D26)/2 -> 0.91687 | E27: =(E25+E26)/2 -> 0.89182 | F27: =(F25+F26)/2 -> 0.86878 | G27: =(G25+G26)/2 -> 0.84724 | H27: =(H25+H26)/2 -> 0.8267 | I27: =(I25+I26)/2 -> 0.80666 | ... U27: =(U25+U26)/2 -> 0.577911
A28: CATL565-6剩余容量
B29: 1 | C29: 2 | D29: 3 | E29: 4 | F29: 5 | G29: 6 | H29: 7 | I29: 8 | J29: 9 | K29: 10 | L29: 11 | M29: 12 | N29: 13 | O29: 14 | P29: 15 | Q29: 16 | R29: 17 | S29: 18 | T29: 19 | U29: 20
A30: 年初 | B30: 1 | C30: 0.96 | D30: 0.93095 | E30: 0.90492 | F30: 0.8809 | G30: 0.85888 | H30: 0.83786 | I30: 0.81784 | J30: 0.79782 | K30: 0.778 | L30: 0.759 | M30: 0.74 | N30: 0.722 | O30: 0.703 | P30: 0.685 | Q30: 0.668 | R30: 0.6481 | S30: 0.634446 | T30: 0.614446 | U30: 0.598119
A31: 年末 | B31: =C30 -> 0.96 | C31: =D30 -> 0.93095 | D31: =E30 -> 0.90492 | E31: =F30 -> 0.8809 | F31: =G30 -> 0.85888 | G31: =H30 -> 0.83786 | H31: =I30 -> 0.81784 | I31: =J30 -> 0.79782 | ... T31: =U30 -> 0.598119 | U31: 0.581792
A32: 综合 | B32: =(B30+B31)/2 -> 0.98 | C32: =(C30+C31)/2 -> 0.945475 | D32: =(D30+D31)/2 -> 0.917935 | E32: =(E30+E31)/2 -> 0.89291 | F32: =(F30+F31)/2 -> 0.86989 | G32: =(G30+G31)/2 -> 0.84837 | H32: =(H30+H31)/2 -> 0.82785 | I32: =(I30+I31)/2 -> 0.80783 | ... U32: =(U30+U31)/2 -> 0.5899555
A33: 640A-6.68剩余容量
B34: 1 | C34: 2 | D34: 3 | E34: 4 | F34: 5 | G34: 6 | H34: 7 | I34: 8 | J34: 9 | K34: 10 | L34: 11 | M34: 12 | N34: 13 | O34: 14 | P34: 15 | Q34: 16 | R34: 17 | S34: 18 | T34: 19 | U34: 20
A35: 年初 | B35: 1 | C35: 0.964 | D35: 0.93763 | E35: 0.91294 | F35: 0.889925 | G35: 0.868628 | H35: 0.848628 | I35: 0.83188 | J35: 0.81288 | K35: 0.79685 | L35: 0.778756 | M35: 0.76285 | N35: 0.750133 | O35: 0.73576 | P35: 0.7237 | Q35: 0.713625 | R35: 0.6984 | S35: 0.68634 | T35: 0.670128 | U35: 0.654916
A36: 年末 | B36: =C35 -> 0.964 | C36: =D35 -> 0.93763 | D36: =E35 -> 0.91294 | E36: =F35 -> 0.889925 | F36: =G35 -> 0.868628 | G36: =H35 -> 0.848628 | H36: =I35 -> 0.83188 | I36: =J35 -> 0.81288 | ... T36: =U35 -> 0.654916 | U36: 0.639704
A37: 综合 | B37: =(B35+B36)/2 -> 0.982 | C37: =(C35+C36)/2 -> 0.950815 | D37: =(D35+D36)/2 -> 0.925285 | E37: =(E35+E36)/2 -> 0.9014325 | F37: =(F35+F36)/2 -> 0.8792765 | G37: =(G35+G36)/2 -> 0.858628 | H37: =(H35+H36)/2 -> 0.840254 | I37: =(I35+I36)/2 -> 0.82238 | ... U37: =(U35+U36)/2 -> 0.64731
A38: 中车648-6.9剩余容量
B39: 1 | C39: 2 | D39: 3 | E39: 4 | F39: 5 | G39: 6 | H39: 7 | I39: 8 | J39: 9 | K39: 10 | L39: 11 | M39: 12 | N39: 13 | O39: 14 | P39: 15 | Q39: 16 | R39: 17 | S39: 18 | T39: 19 | U39: 20
A40: 年初 | B40: 1 | C40: 0.961 | D40: 0.932 | E40: 0.906 | F40: 0.882 | G40: 0.86 | H40: 0.839 | I40: 0.819 | J40: 0.799 | K40: 0.78 | L40: 0.762 | M40: 0.744 | N40: 0.727 | O40: 0.709 | P40: 0.692 | Q40: 0.676 | R40: 0.659 | S40: 0.643 | T40: 0.626 | U40: 0.61
A41: 年末 | B41: =C40 -> 0.961 | C41: =D40 -> 0.932 | D41: =E40 -> 0.906 | E41: =F40 -> 0.882 | F41: =G40 -> 0.86 | G41: =H40 -> 0.839 | H41: =I40 -> 0.819 | I41: =J40 -> 0.799 | ... T41: =U40 -> 0.61 | U41: 0.594
A42: 综合 | B42: =(B40+B41)/2 -> 0.9805 | C42: =(C40+C41)/2 -> 0.9465 | D42: =(D40+D41)/2 -> 0.919 | E42: =(E40+E41)/2 -> 0.894 | F42: =(F40+F41)/2 -> 0.871 | G42: =(G40+G41)/2 -> 0.8495 | H42: =(H40+H41)/2 -> 0.829 | I42: =(I40+I41)/2 -> 0.809 | ... U42: =(U40+U41)/2 -> 0.602
...

Sheet 经济性测算
A1: 收入 | AA1: 年折旧费 | AB1: 增值税抵扣
A2: 放电量 | C2: 1 | D2: 2 | E2: 3 | F2: 4 | G2: 5 | H2: 6 | I2: 7 | J2: 8 | K2: 9 | L2: 10 | M2: 11 | N2: 12 | O2: 13 | P2: 14 | Q2: 15 | R2: 16 | S2: 17 | T2: 18 | U2: 19 | V2: 20 | AA2: =(展示总表!D6+展示总表!E6+展示总表!F6-施工耗材基建成本构成!F44-(展示总表!D6+展示总表!E6+展示总表!F6-施工耗材基建成本构成!F44)/1.13*0.13)*0.95/累计充电电费及累计放电量!J9 -> 10880329 | AB2: =(展示总表!D6+展示总表!E6+展示总表!F6-施工耗材基建成本构成!F44)/1.13*0.13 -> 28288856
C3: =累计充电电费及累计放电量!B77 -> 1.2248965e+08 | D3: =累计充电电费及累计放电量!C77 -> 1.198927e+08 | E3: =累计充电电费及累计放电量!D77 -> 1.1735758e+08 | F3: =累计充电电费及累计放电量!E77 -> 1.1494612e+08 | G3: =累计充电电费及累计放电量!F77 -> 1.1259649e+08 | H3: =累计充电电费及累计放电量!G77 -> 1.1037053e+08 | I3: =累计充电电费及累计放电量!H77 -> 1.0826824e+08 | J3: =累计充电电费及累计放电量!I77 -> 1.0604228e+08 | ... V3: =累计充电电费及累计放电量!U77 -> FALSE
A4: 调频收益 | C4: =IF(累计充电电费及累计放电量!$J$9>经济性测算!C2-1,累计充电电费及累计放电量!$J$14*累计充电电费及累计放电量!$J$4,0) -> 20000000 | D4: =IF(累计充电电费及累计放电量!$J$9>经济性测算!D2-1,累计充电电费及累计放电量!$J$14*累计充电电费及累计放电量!$J$4,0) -> 20000000 | E4: =IF(累计充电电费及累计放电量!$J$9>经济性测算!E2-1,累计充电电费及累计放电量!$J$14*累计充电电费及累计放电量!$J$4,0) -> 20000000 | F4: =IF(累计充电电费及累计放电量!$J$9>经济性测算!F2-1,累计充电电费及累计放电量!$J$14*累计充电电费及累计放电量!$J$4,0) -> 20000000 | G4: =IF(累计充电电费及累计放电量!$J$9>经济性测算!G2-1,累计充电电费及累计放电量!$J$14*累计充电电费及累计放电量!$J$4,0) -> 20000000 | H4: =IF(累计充电电费及累计放电量!$J$9>经济性测算!H2-1,累计充电电费及累计放电量!$J$14*累计充电电费及累计放电量!$J$4,0) -> 20000000 | I4: =IF(累计充电电费及累计放电量!$J$9>经济性测算!I2-1,累计充电电费及累计放电量!$J$14*累计充电电费及累计放电量!$J$4,0) -> 20000000 | J4: =IF(累计充电电费及累计放电量!$J$9>经济性测算!J2-1,累计充电电费及累计放电量!$J$14*累计充电电费及累计放电量!$J$4,0) -> 20000000 | ... V4: =IF(累计充电电费及累计放电量!$J$9>经济性测算!V2-1,累计充电电费及累计放电量!$J$14*累计充电电费及累计放电量!$J$4,0) -> 0
A5: 容量电费 | C5: =IF(累计充电电费及累计放电量!$J$9>经济性测算!C2-1,累计充电电费及累计放电量!$J$15*1000*累计充电电费及累计放电量!$J$4/2,0) -> 10000000 | D5: =IF(累计充电电费及累计放电量!$J$9>经济性测算!D2-1,累计充电电费及累计放电量!$J$15*1000*累计充电电费及累计放电量!$J$4/2,0) -> 10000000 | E5: =IF(累计充电电费及累计放电量!$J$9>经济性测算!E2-1,累计充电电费及累计放电量!$J$15*1000*累计充电电费及累计放电量!$J$4/2,0) -> 10000000 | F5: =IF(累计充电电费及累计放电量!$J$9>经济性测算!F2-1,累计充电电费及累计放电量!$J$15*1000*累计充电电费及累计放电量!$J$4/2,0) -> 10000000 | G5: =IF(累计充电电费及累计放电量!$J$9>经济性测算!G2-1,累计充电电费及累计放电量!$J$15*1000*累计充电电费及累计放电量!$J$4/2,0) -> 10000000 | H5: =IF(累计充电电费及累计放电量!$J$9>经济性测算!H2-1,累计充电电费及累计放电量!$J$15*1000*累计充电电费及累计放电量!$J$4/2,0) -> 10000000 | I5: =IF(累计充电电费及累计放电量!$J$9>经济性测算!I2-1,累计充电电费及累计放电量!$J$15*1000*累计充电电费及累计放电量!$J$4/2,0) -> 10000000 | J5: =IF(累计充电电费及累计放电量!$J$9>经济性测算!J2-1,累计充电电费及累计放电量!$J$15*1000*累计充电电费及累计放电量!$J$4/2,0) -> 10000000 | ... V5: =IF(累计充电电费及累计放电量!$J$9>经济性测算!V2-1,累计充电电费及累计放电量!$J$15*1000*累计充电电费及累计放电量!$J$4/2,0) -> 0
A6: 售电金额 | C6: =C3*累计充电电费及累计放电量!$J$13 -> 53160508 | D6: =D3*累计充电电费及累计放电量!$J$13 -> 52033430 | E6: =E3*累计充电电费及累计放电量!$J$13 -> 50933188 | F6: =F3*累计充电电费及累计放电量!$J$13 -> 49886615 | G6: =G3*累计充电电费及累计放电量!$J$13 -> 48866878 | H6: =H3*累计充电电费及累计放电量!$J$13 -> 47900811 | I6: =I3*累计充电电费及累计放电量!$J$13 -> 46988415 | J6: =J3*累计充电电费及累计放电量!$J$13 -> 46022348 | ... V6: =V3*累计充电电费及累计放电量!$J$13 -> 0
A8: 支出 | C8: 1 | D8: 2 | E8: 3 | F8: 4 | G8: 5 | H8: 6 | I8: 7 | J8: 8 | K8: 9 | L8: 10 | M8: 11 | N8: 12 | O8: 13 | P8: 14 | Q8: 15 | R8: 16 | S8: 17 | T8: 18 | U8: 19 | V8: 20
A9: 充电量 | C9: =累计充电电费及累计放电量!B76 -> 1.4137943e+08 | D9: =累计充电电费及累计放电量!C76 -> 1.3838199e+08 | E9: =累计充电电费及累计放电量!D76 -> 1.3545591e+08 | F9: =累计充电电费及累计放电量!E76 -> 1.3267257e+08 | G9: =累计充电电费及累计放电量!F76 -> 1.299606e+08 | H9: =累计充电电费及累计放电量!G76 -> 1.2739136e+08 | I9: =累计充电电费及累计放电量!H76 -> 1.2496486e+08 | J9: =累计充电电费及累计放电量!I76 -> 1.2239562e+08 | ... V9: =累计充电电费及累计放电量!U76 -> FALSE
A10: 购电金额 | C10: =C9*累计充电电费及累计放电量!$J$12 -> 14137943 | D10: =D9*累计充电电费及累计放电量!$J$12 -> 13838199 | E10: =E9*累计充电电费及累计放电量!$J$12 -> 13545591 | F10: =F9*累计充电电费及累计放电量!$J$12 -> 13267257 | G10: =G9*累计充电电费及累计放电量!$J$12 -> 12996060 | H10: =H9*累计充电电费及累计放电量!$J$12 -> 12739136 | I10: =I9*累计充电电费及累计放电量!$J$12 -> 12496486 | J10: =J9*累计充电电费及累计放电量!$J$12 -> 12239562 | ... V10: =V9*累计充电电费及累计放电量!$J$12 -> 0
A11: 设备折旧 | C11: =IF(累计充电电费及累计放电量!$J$9+1>经济性测算!C8,经济性测算!$AA$2,0) -> 10880329 | D11: =IF(累计充电电费及累计放电量!$J$9+1>经济性测算!D8,经济性测算!$AA$2,0) -> 10880329 | E11: =IF(累计充电电费及累计放电量!$J$9+1>经济性测算!E8,经济性测算!$AA$2,0) -> 10880329 | F11: =IF(累计充电电费及累计放电量!$J$9+1>经济性测算!F8,经济性测算!$AA$2,0) -> 10880329 | G11: =IF(累计充电电费及累计放电量!$J$9+1>经济性测算!G8,经济性测算!$AA$2,0) -> 10880329 | H11: =IF(累计充电电费及累计放电量!$J$9+1>经济性测算!H8,经济性测算!$AA$2,0) -> 10880329 | I11: =IF(累计充电电费及累计放电量!$J$9+1>经济性测算!I8,经济性测算!$AA$2,0) -> 10880329 | J11: =IF(累计充电电费及累计放电量!$J$9+1>经济性测算!J8,经济性测算!$AA$2,0) -> 10880329 | ... V11: =IF(累计充电电费及累计放电量!$J$9+1>经济性测算!V8,经济性测算!$AA$2,0) -> 0
A12: OPEX | C12: =运营期间费用构成!C11 -> 2906953.7 | D12: =运营期间费用构成!D11 -> 2906953.7 | E12: =运营期间费用构成!E11 -> 3146953.7 | F12: =运营期间费用构成!F11 -> 2906953.7 | G12: =运营期间费用构成!G11 -> 3210953.7 | H12: =运营期间费用构成!H11 -> 3146953.7 | I12: =运营期间费用构成!I11 -> 2906953.7 | J12: =运营期间费用构成!J11 -> 2906953.7 | ... V12: =运营期间费用构成!V11 -> 0
A15: 利润
A16: 毛利润 | C16: =C4+C5+C6-C10 -> 69022565 | D16: =D4+D5+D6-D10 -> 68195232 | E16: =E4+E5+E6-E10 -> 67387597 | F16: =F4+F5+F6-F10 -> 66619358 | G16: =G4+G5+G6-G10 -> 65870818 | H16: =H4+H5+H6-H10 -> 65161675 | I16: =I4+I5+I6-I10 -> 64491929 | J16: =J4+J5+J6-J10 -> 63782786 | ... V16: =V4+V5+V6-V10 -> 0
A17: 增值税应缴 | C17: =C16*0.13 -> 8972933.5 | D17: =D16*0.13 -> 8865380.1 | E17: =E16*0.13 -> 8760387.5 | F17: =F16*0.13 -> 8660516.6 | G17: =G16*0.13 -> 8563206.4 | H17: =H16*0.13 -> 8471017.8 | I17: =I16*0.13 -> 8383950.8 | J17: =J16*0.13 -> 8291762.2 | ... V17: =V16*0.13 -> 0
A18: 增值税抵扣 | C18: =IF(AB2-C17>0,C17,0) -> 8972933.5 | D18: =IF(AB2-C17-D17>0,D17,0) -> 8865380.1 | E18: =IF(AB2-C17-D17-E17>0,E17,0) -> 8760387.5 | F18: 0 | G18: 0 | H18: 0 | I18: 0 | J18: 0 | K18: 0 | L18: 0 | M18: 0 | N18: 0 | O18: 0 | P18: 0 | Q18: 0 | R18: 0 | S18: 0 | T18: 0 | U18: 0 | V18: 0
A19: 增值税实缴 | C19: =C17-C18 -> 0 | D19: =D17-D18 -> 0 | E19: =E17-E18 -> 0 | F19: =F17-F18 -> 8660516.6 | G19: =G17-G18 -> 8563206.4 | H19: =H17-H18 -> 8471017.8 | I19: =I17-I18 -> 8383950.8 | J19: =J17-J18 -> 8291762.2 | ... V19: =V17-V18 -> 0
A20: 当期现金收入 | C20: =C16-C19 -> 69022565 | D20: =D16-D19 -> 68195232 | E20: =E16-E19 -> 67387597 | F20: =F16-F19 -> 57958842 | G20: =G16-G19 -> 57307612 | H20: =H16-H19 -> 56690658 | I20: =I16-I19 -> 56107978 | J20: =J16-J19 -> 55491024 | ... V20: =V16-V19 -> 0
A21: 利润总额 | C21: =C20-C11-C12 -> 55235282 | D21: =D20-D11-D12 -> 54407949 | E21: =E20-E11-E12 -> 53360314 | F21: =F20-F11-F12 -> 44171559 | G21: =G20-G11-G12 -> 43216329 | H21: =H20-H11-H12 -> 42663375 | I21: =I20-I11-I12 -> 42320695 | J21: =J20-J11-J12 -> 41703741 | ... V21: =V20-V11-V12 -> 0
A22: 所得税 | C22: =C21*0.25 -> 13808821 | D22: =D21*0.25 -> 13601987 | E22: =E21*0.25 -> 13340078 | F22: =F21*0.25 -> 11042890 | G22: =G21*0.25 -> 10804082 | H22: =H21*0.25 -> 10665844 | I22: =I21*0.25 -> 10580174 | J22: =J21*0.25 -> 10425935 | ... V22: =V21*0.25 -> 0
A23: 净利润 | B23: =SUM(C23:V23) -> 9.9172473e+08 | C23: =C16-C22 -> 55213745 | D23: =D16-D22 -> 54593244 | E23: =E16-E22 -> 54047518 | F23: =F16-F22 -> 55576469 | G23: =G16-G22 -> 55066736 | H23: =H16-H22 -> 54495832 | I23: =I16-I22 -> 53911755 | J23: =J16-J22 -> 53356851 | ... V23: =V16-V22 -> 0
A24: 现金流 | B24: =-(展示总表!D6+展示总表!E6+展示总表!F6) -> -2.539639e+08 | C24: =C20-(C22+C12) -> 52306791 | D24: =D20-(D22+D12) -> 51686291 | E24: =E20-(E22+E12) -> 50900564 | F24: =F20-(F22+F12) -> 44008998 | G24: =G20-(G22+G12) -> 43292576 | H24: =H20-(H22+H12) -> 42877860 | I24: =I20-(I22+I12) -> 42620851 | J24: =J20-(J22+J12) -> 42158135 | ... V24: =V20-(V22+V12) -> 0
A25: IRR | B25: =IRR(B24:V24) -> 0.17124928 | C25: =IRR(B24:C24) -> -0.79403848 | D25: =IRR(B24:D24) -> -0.43428465 | E25: =IRR(B24:E24) -> -0.21246224 | F25: =IRR(B24:F24) -> -0.093302963 | G25: =IRR(B24:G24) -> -0.016173626 | H25: =IRR(B24:H24) -> 0.035520618 | I25: =IRR(B24:I24) -> 0.071381824 | J25: =IRR(B24:J24) -> 0.096844868 | K25: =IRR(B24:K24) -> 0.11531493 | L25: =IRR(B24:L24) -> 0.12903467 | M25: =IRR(B24:M24) -> 0.13939422 | N25: =IRR(B24:N24) -> 0.14731138 | O25: =IRR(B24:O24) -> 0.15348976 | P25: =IRR(B24:P24) -> 0.15833746 | Q25: =IRR(B24:Q24) -> 0.16213677 | R25: =IRR(B24:R24) -> 0.16520058 | S25: =IRR(B24:S24) -> 0.1676603 | T25: =IRR(B24:T24) -> 0.16963748 | U25: =IRR(B24:U24) -> 0.17124928 | V25: =IRR(B24:V24) -> 0.17124928
A26: 全投资累计现金流 | B26: =B24 -> -2.539639e+08 | C26: =C24+B26 -> -2.0165711e+08 | D26: =D24+C26 -> -1.4997082e+08 | E26: =E24+D26 -> -99070251 | F26: =F24+E26 -> -55061253 | G26: =G24+F26 -> -11768677 | H26: =H24+G26 -> 31109183 | I26: =I24+H26 -> 73730034 | J26: =J24+I26 -> 1.1588817e+08 | ... V26: =V24+U26 -> 5.4843857e+08
C27: =IF(C26*B26<0,1,0) -> 0 | D27: =IF(D26*C26<0,1,0) -> 0 | E27: =IF(E26*D26<0,1,0) -> 0 | F27: =IF(F26*E26<0,1,0) -> 0 | G27: =IF(G26*F26<0,1,0) -> 0 | H27: =IF(H26*G26<0,1,0) -> 1 | I27: =IF(I26*H26<0,1,0) -> 0 | J27: =IF(J26*I26<0,1,0) -> 0 | ... V27: =IF(V26*U26<0,1,0) -> 0
A28: 回收年限 | B28: =SUM(C28:V28) -> 5.2744698 | C28: =IF(C27=1,B2+(0-B26)/C24,0) -> 0 | D28: =IF(D27=1,C2+(0-C26)/D24,0) -> 0 | E28: =IF(E27=1,D2+(0-D26)/E24,0) -> 0 | F28: =IF(F27=1,E2+(0-E26)/F24,0) -> 0 | G28: =IF(G27=1,F2+(0-F26)/G24,0) -> 0 | H28: =IF(H27=1,G2+(0-G26)/H24,0) -> 5.2744698 | I28: =IF(I27=1,H2+(0-H26)/I24,0) -> 0 | J28: =IF(J27=1,I2+(0-I26)/J24,0) -> 0 | ... V28: =IF(V27=1,U2+(0-U26)/V24,0) -> 0
H31: 25259324 | I31: 68300980 | J31: 1.1077969e+08 | K31: 1.5254105e+08
H32: 8845237.6 | I32: 51701351 | J32: 94094748 | K32: 1.3588399e+08 | L32: 1.7720107e+08 | M32: 2.18022e+08 | N32: 2.5825163e+08 | O32: 2.9824995e+08 | P32: 3.3783697e+08 | Q32: 3.7661754e+08
C34: -1.8250699e+08 | D34: -1.3019591e+08 | E34: -78947190 | F34: -34609944 | G34: 8846800.9 | H34: 51750222 | I34: 94257907 | J34: 1.3620265e+08 | K34: 1.7743004e+08 | L34: 2.1808487e+08 | M34: 2.5815593e+08 | N34: 2.5815593e+08 | O34: 2.5815593e+08
